Workbook

Sheet 원격정보
B1: AXGate Client VPN 접속 IP
N2: 마지막 수정일 : | O2: =TODAY() -> 45931
B3: 지역 | E3: VPN 정보 | J3: Server 정보 | N3: 비고
B4: BrdCode | C4: 시/도 | D4: 시/군 | E4: 모델명 | F4: IP : Port | G4: 인증 IP : Port | H4: ID | I4: Password | J4: 서버명 | K4: IP : Port | L4: ID | M4: Password | N4: 비고 작성일 | O4: 내용
B5: =IF(D5="","",VLOOKUP(D5,지역코드!$A$2:$C$163,2,0)) -> 5 | C5: =IF(D5="","",VLOOKUP(D5,지역코드!$A$2:$C$163,3,0)) -> 세종 | D5: 세종 | J5: 침수차단 관측서버 | M5: qwer123$ | O5: 폐쇄망
B6: =IF(D6="","",VLOOKUP(D6,지역코드!$A$2:$C$163,2,0)) -> 9 | C6: =IF(D6="","",VLOOKUP(D6,지역코드!$A$2:$C$163,3,0)) -> 제주 | D6: 제주 | H6: 1 701 027 987 | I6: woobosys | J6: 기상관측서버 | K6: 192.168.2.150:16100 | O6: 썸 관리(팀뷰어 통해서 접속)
B7: =IF(D7="","",VLOOKUP(D7,지역코드!$A$2:$C$163,2,0)) -> 8 | C7: =IF(D7="","",VLOOKUP(D7,지역코드!$A$2:$C$163,3,0)) -> 제주 | D7: 서귀포 | J7: Woobo 관측서버 | K7: 211.34.191.202 | L7: snowdata | M7: 안전100% | O7: 상황실 모니터링중
B8: =IF(D8="","",VLOOKUP(D8,지역코드!$A$2:$C$163,2,0)) -> 10 | C8: =IF(D8="","",VLOOKUP(D8,지역코드!$A$2:$C$163,3,0)) -> 강원 | D8: 강릉 | F8: 152.99.143.151:7900 | G8: 172.16.0.1:8081 | H8: gangneung | I8: admin123! | J8: Woobo 관측서버 | K8: 20.150.0.100:13389 | L8: administrator | M8: !086Piy?
B9: =IF(D9="","",VLOOKUP(D9,지역코드!$A$2:$C$163,2,0)) -> 10 | C9: =IF(D9="","",VLOOKUP(D9,지역코드!$A$2:$C$163,3,0)) -> 강원 | D9: 강릉 | F9: 152.99.143.151:7900 | G9: 172.16.0.1:8081 | H9: gangneung | I9: admin123! | J9: Amano 중계서버 | K9: 20.150.5.7:13389 | L9: administrator | M9: !086Piy?
B10: =IF(D10="","",VLOOKUP(D10,지역코드!$A$2:$C$163,2,0)) -> 15 | C10: =IF(D10="","",VLOOKUP(D10,지역코드!$A$2:$C$163,3,0)) -> 강원 | D10: 양구 | F10: 221.144.206.176:7900 | G10: 172.16.0.1:8081 | H10: yanggu | I10: admin123! | K10: 192.168.0.110:22000 | L10: draws_was | M10: didrn12#$ | O10: 접속시 주의! (부린)
B11: =IF(D11="","",VLOOKUP(D11,지역코드!$A$2:$C$163,2,0)) -> 17 | C11: =IF(D11="","",VLOOKUP(D11,지역코드!$A$2:$C$163,3,0)) -> 강원 | D11: 영월 | F11: 152.99.160.122:7900 | G11: 172.16.0.1:8081 | H11: yeongwol | I11: admin123! | J11: 관측서버 | K11: 20.200.0.100:13389 | L11: administrator | M11: !086Piy?
B12: =IF(D12="","",VLOOKUP(D12,지역코드!$A$2:$C$163,2,0)) -> 17 | C12: =IF(D12="","",VLOOKUP(D12,지역코드!$A$2:$C$163,3,0)) -> 강원 | D12: 영월 | F12: 152.99.160.122:7900 | G12: 172.16.0.1:8081 | H12: yeongwol | I12: admin123! | J12: KIOT 수집서버 | K12: 20.200.0.101:3389 | L12: administrator | M12: yeongwol1!
B13: =IF(D13="","",VLOOKUP(D13,지역코드!$A$2:$C$163,2,0)) -> 18 | C13: =IF(D13="","",VLOOKUP(D13,지역코드!$A$2:$C$163,3,0)) -> 강원 | D13: 원주 | F13: 152.99.142.107:7900 | G13: 172.16.0.1:8081 | H13: wonju | I13: admin123! | J13: Woobo 관측서버 | K13: 20.200.0.100:13389 | L13: administrator | M13: !086Piy?
B14: =IF(D14="","",VLOOKUP(D14,지역코드!$A$2:$C$163,2,0)) -> 18 | C14: =IF(D14="","",VLOOKUP(D14,지역코드!$A$2:$C$163,3,0)) -> 강원 | D14: 원주 | F14: 152.99.142.107:7900 | G14: 172.16.0.1:8081 | H14: wonju | I14: admin123! | J14: Woobo DB서버 | K14: 152.99.142.108:23389 | L14: administrator | M14: !086Piy? | O14: 관측서버에서만 접근가능
B15: =IF(D15="","",VLOOKUP(D15,지역코드!$A$2:$C$163,2,0)) -> 18 | C15: =IF(D15="","",VLOOKUP(D15,지역코드!$A$2:$C$163,3,0)) -> 강원 | D15: 원주 | J15: 침수서버 | K15: 152.99.142.60:13389 | L15: administrator | M15: !086Piy?
B16: =IF(D16="","",VLOOKUP(D16,지역코드!$A$2:$C$163,2,0)) -> 20 | C16: =IF(D16="","",VLOOKUP(D16,지역코드!$A$2:$C$163,3,0)) -> 강원 | D16: 정선 | F16: 152.99.171.181:7900 | G16: 172.16.0.1:8081 | H16: jeongseon | I16: admin123! | J16: Woobo 관측서버 | K16: 20.79.0.100 | L16: administrator | M16: !086Piy? | O16: 2022.08.16 VPN로그인안됨, 씨트롤 가능
B17: =IF(D17="","",VLOOKUP(D17,지역코드!$A$2:$C$163,2,0)) -> 21 | C17: =IF(D17="","",VLOOKUP(D17,지역코드!$A$2:$C$163,3,0)) -> 강원 | D17: 철원 | F17: 152.99.172.86:7900 | G17: 172.16.0.1:8081 | H17: cheorwon | I17: admin123! | J17: 관측서버 | K17: 20.200.0.100:13389 | L17: administrator | M17: !086Piy? | N17: cas/cas
B18: =IF(D18="","",VLOOKUP(D18,지역코드!$A$2:$C$163,2,0)) -> 25 | C18: =IF(D18="","",VLOOKUP(D18,지역코드!$A$2:$C$163,3,0)) -> 강원 | D18: 홍천 | F18: 152.99.148.188:7900 | G18: 172.16.0.1:8081 | H18: hongcheon | I18: admin123! | J18: Woobo 관측서버 | K18: 152.99.148.155:13389 | L18: administrator | M18: !086Piy? | O18: 2025.02.03 VPN로그인됨, 원격안됨
B19: =IF(D19="","",VLOOKUP(D19,지역코드!$A$2:$C$163,2,0)) -> 27 | C19: =IF(D19="","",VLOOKUP(D19,지역코드!$A$2:$C$163,3,0)) -> 강원 | D19: 횡성 | F19: 152.99.149.180:7900 | G19: 172.16.0.1:8081 | H19: hoengseong | I19: admin123! | J19: Woobo DB서버 | K19: 106.9.91.204:13389 (152.99.149.181:13306) | L19: Administrator | M19: !086Piy?
B20: =IF(D20="","",VLOOKUP(D20,지역코드!$A$2:$C$163,2,0)) -> 43 | C20: =IF(D20="","",VLOOKUP(D20,지역코드!$A$2:$C$163,3,0)) -> 경기 | D20: 안성 | F20: 27.101.130.178:7900 | G20: 172.16.0.1:8081 | H20: anseong | I20: admin123! | J20: 수위계측 관측서버 | K20: 20.160.0.100:3389 | L20: administrator | M20: !086Piy?
B21: =IF(D21="","",VLOOKUP(D21,지역코드!$A$2:$C$163,2,0)) -> 43 | C21: =IF(D21="","",VLOOKUP(D21,지역코드!$A$2:$C$163,3,0)) -> 경기 | D21: 안성 | F21: 27.101.130.121:7800 | G21: 172.16.0.1:7981 | H21: anseong | I21: admin123! | J21: 둔치주차 관측서버 | K21: 27.101.130.122:13389 / 20.200.0.100 | L21: administrator | M21: !086Piy?
B22: =IF(D22="","",VLOOKUP(D22,지역코드!$A$2:$C$163,2,0)) -> 43 | C22: =IF(D22="","",VLOOKUP(D22,지역코드!$A$2:$C$163,3,0)) -> 경기 | D22: 안성 | F22: 59.13.176.11:7900 | G22: 172.16.0.1:8081 | H22: anseong | I22: admin123! | J22: 급경사지 관측서버 | K22: 20.210.0.100 | O22: 심플비트
B23: =IF(D23="","",VLOOKUP(D23,지역코드!$A$2:$C$163,2,0)) -> 53 | C23: =IF(D23="","",VLOOKUP(D23,지역코드!$A$2:$C$163,3,0)) -> 경기 | D23: 이천 | E23: Axgate90 | F23: 27.101.121.150:7900 | G23: 172.16.0.1:8081 | H23: icheon | I23: admin123! | J23: Woobo 관측서버 | K23: 20.190.0.100:13389 | L23: administrator | M23: !086Piy? | N23: 44749 | O23: 20.190.0.0 대역만 접근 가능
B24: =IF(D24="","",VLOOKUP(D24,지역코드!$A$2:$C$163,2,0)) -> 74 | C24: =IF(D24="","",VLOOKUP(D24,지역코드!$A$2:$C$163,3,0)) -> 경남 | D24: 함안 | F24: 27.101.82.211:7900 | G24: 172.16.0.1:8081 | H24: haman | I24: admin123! | J24: 관측서버 | K24: 27.101.82.210 / 20.60.0.100:13389 | L24: administrator / WBEarly | M24: !086Piy? | N24: 45034 | O24: 서브계정사용
B25: =IF(D25="","",VLOOKUP(D25,지역코드!$A$2:$C$163,2,0)) -> 82 | C25: =IF(D25="","",VLOOKUP(D25,지역코드!$A$2:$C$163,3,0)) -> 경북 | D25: 김천 | J25: 관측서버 | K25: 172.4.1.10 | L25: administrator | M25: !123qwe
B26: =IF(D26="","",VLOOKUP(D26,지역코드!$A$2:$C$163,2,0)) -> 86 | C26: =IF(D26="","",VLOOKUP(D26,지역코드!$A$2:$C$163,3,0)) -> 경북 | D26: 성주 | F26: 27.101.28.43:7900 | G26: 172.16.0.1:8081 | H26: seongju | I26: admin123! | K26: 20.120.0.100:13389 | L26: administrator | M26: !086Piy?
B27: =IF(D27="","",VLOOKUP(D27,지역코드!$A$2:$C$163,2,0)) -> 88 | C27: =IF(D27="","",VLOOKUP(D27,지역코드!$A$2:$C$163,3,0)) -> 경북 | D27: 영덕 | F27: 27.101.25.144:7900 | G27: 172.16.0.1:8081 | H27: yeongdeok | I27: admin123! | J27: 관측서버 | K27: 20.70.0.100:13389 | L27: administrator | M27: !086Piy?
B28: =IF(D28="","",VLOOKUP(D28,지역코드!$A$2:$C$163,2,0)) -> 91 | C28: =IF(D28="","",VLOOKUP(D28,지역코드!$A$2:$C$163,3,0)) -> 경북 | D28: 영천 | F28: 27.101.17.165:7900 | G28: 172.16.0.1:8081 | H28: yeongcheon | I28: admin123! | J28: Woobo 관측서버 | K28: 20.200.0.100:13389 | L28: administrator | M28: !086Piy?
B29: =IF(D29="","",VLOOKUP(D29,지역코드!$A$2:$C$163,2,0)) -> 95 | C29: =IF(D29="","",VLOOKUP(D29,지역코드!$A$2:$C$163,3,0)) -> 경북 | D29: 의성 | F29: 27.101.22.21:7900 | G29: 172.16.0.1:8081 | H29: uiseong | I29: admin123! | J29: 조기경보 관측서버 | K29: 20.200.0.100:13389 | L29: administrator | M29: !086Piy?
B30: =IF(D30="","",VLOOKUP(D30,지역코드!$A$2:$C$163,2,0)) -> 95 | C30: =IF(D30="","",VLOOKUP(D30,지역코드!$A$2:$C$163,3,0)) -> 경북 | D30: 의성 | F30: 27.101.22.40:7900 | G30: 172.16.0.1:8081 | H30: uiseong | I30: admin123! | J30: 침수차단 관측서버 | K30: 20.200.0.100:13389 | L30: administrator | M30: !086Piy?
B31: =IF(D31="","",VLOOKUP(D31,지역코드!$A$2:$C$163,2,0)) -> 97 | C31: =IF(D31="","",VLOOKUP(D31,지역코드!$A$2:$C$163,3,0)) -> 경북 | D31: 청송 | F31: 27.101.23.41:? | G31: 네오컨넥트 | J31: 관측서버 | K31: 172.10.0.10:16100 | L31: csadmin | M31: !086Piy? | N31: 44977 | O31: 네오커넥트/ mstsc 원격불가(보안) / DB 확인가능
B32: =IF(D32="","",VLOOKUP(D32,지역코드!$A$2:$C$163,2,0)) -> 107 | C32: =IF(D32="","",VLOOKUP(D32,지역코드!$A$2:$C$163,3,0)) -> 전남 | D32: 목포 | G32: AnyDesk | K32: 110.1.29.111 | L32: 569 639 686 | M32: qwe123!@# | N32: 44872 | O32: 담당자가 보고있습니다!! 창 정리 필수!!
B33: =IF(D33="","",VLOOKUP(D33,지역코드!$A$2:$C$163,2,0)) -> 108 | C33: =IF(D33="","",VLOOKUP(D33,지역코드!$A$2:$C$163,3,0)) -> 전남 | D33: 무안 | F33: 152.99.184.41:7900 | G33: 172.16.0.1:8081 | H33: muan | I33: admin123! | J33: Woobo 관측서버 | K33: 20.170.0.100:13389 | L33: administrator | M33: !086Piy?
B34: =IF(D34="","",VLOOKUP(D34,지역코드!$A$2:$C$163,2,0)) -> 122 | C34: =IF(D34="","",VLOOKUP(D34,지역코드!$A$2:$C$163,3,0)) -> 전북 | D34: 고창 | F34: 27.101.163.35:7900 | G34: 172.16.0.1:8081 | H34: gochang | I34: admin123! | J34: Woobo 관측서버 | K34: 20.130.0.100:13389 | L34: administrator | M34: !086Piy?
B35: =IF(D35="","",VLOOKUP(D35,지역코드!$A$2:$C$163,2,0)) -> 124 | C35: =IF(D35="","",VLOOKUP(D35,지역코드!$A$2:$C$163,3,0)) -> 전북 | D35: 김제 | F35: 27.101.156.106:7900 | G35: 172.16.0.1:8081 | H35: gimje | I35: admin123! | J35: Woobo 수집서버(DB) | K35: 27.101.156.103 | L35: cas | M35: cas | O35: 온품방송서버
B36: =IF(D36="","",VLOOKUP(D36,지역코드!$A$2:$C$163,2,0)) -> 124 | C36: =IF(D36="","",VLOOKUP(D36,지역코드!$A$2:$C$163,3,0)) -> 전북 | D36: 김제 | F36: 27.101.156.106:7900 | G36: 172.16.0.1:8081 | H36: gimje | I36: admin123! | J36: Woobo 모니터링PC | K36: 27.101.156.104 | L36: cas | M36: cas | O36: 관제PC(모니터연결중, 접근금지)
B37: =IF(D37="","",VLOOKUP(D37,지역코드!$A$2:$C$163,2,0)) -> 124 | C37: =IF(D37="","",VLOOKUP(D37,지역코드!$A$2:$C$163,3,0)) -> 전북 | D37: 김제 | F37: 27.101.156.106:7900 | G37: 172.16.0.1:8081 | H37: gimje | I37: admin123! | J37: Woobo DB서버 | K37: 27.101.156.105 | L37: cas | M37: cas | O37: 통합전파플랫폼?
B38: =IF(D38="","",VLOOKUP(D38,지역코드!$A$2:$C$163,2,0)) -> 124 | C38: =IF(D38="","",VLOOKUP(D38,지역코드!$A$2:$C$163,3,0)) -> 전북 | D38: 김제 | F38: 27.101.156.106:7900 | G38: 172.16.0.1:8081 | H38: gimje | I38: admin123! | J38: 관측서버 | K38: 20.200.0.100 | L38: administrator | M38: !086Piy? | O38: KVM 연결됨
B39: =IF(D39="","",VLOOKUP(D39,지역코드!$A$2:$C$163,2,0)) -> 135 | C39: =IF(D39="","",VLOOKUP(D39,지역코드!$A$2:$C$163,3,0)) -> 전북 | D39: 진안 | F39: 106.255.233.226:7900 | G39: 172.16.0.1:8081 | H39: jinan | I39: admin123! | J39: Woobo 관측서버 | K39: 20.180.0.100:13389 | L39: administrator | M39: !086Piy?
B40: =IF(D40="","",VLOOKUP(D40,지역코드!$A$2:$C$163,2,0)) -> 137 | C40: =IF(D40="","",VLOOKUP(D40,지역코드!$A$2:$C$163,3,0)) -> 충남 | D40: 공주 | F40: 210.123.195.126:7900 | G40: 172.16.0.1:8081 | H40: gongju | I40: admin123! | J40: Woobo 관측서버 | K40: 210.123.195.125:13389 | L40: administrator | M40: !086Piy?
...

Sheet 지역정보
A2: 지역 | E2: 재해위험지역코드 | G2: 지구명 | Y2: 위험경보발령 임계치
D3: 도입년도 | H3: 일련번호 | I3: 명칭 | L3: 종류 | M3: 장비명 | N3: 모델명 | O3: 버전 | P3: 주소 | R3: 위도 | S3: 경도 | T3: CID | U3: G/W | V3: IP | W3: PORT | X3: 수위 | AD3: 확인 | AE3: 비고 | AF3: 유지보수
A4: 코드 | B4: 시/도 | C4: 시/군 | E4: 법정동코드 | F4: 종류 | X4: EL값 | Y4: 관심(01) | Z4: 주의(02) | AA4: 경계(03) | AB4: 심각(04) | AC4: 대피(05) | AD4: (□ / ■)
A5: 서울시청 / 동대문구 적설관측시스템 구매 설치
A6: =IF(C6="","",VLOOKUP(C6,지역코드!$A$2:$C$163,2,0)) -> 0 | B6: 서울 | C6: 서울
A8: 광주시청 / 장등저수지
A9: =IF(C9="","",VLOOKUP(C9,지역코드!$A$2:$C$163,2,0)) -> 1 | B9: =IF(C9="","",VLOOKUP(C9,지역코드!$A$2:$C$163,3,0)) -> 광주 | C9: 광주 | I9: 서버
A10: =IF(C10="","",VLOOKUP(C10,지역코드!$A$2:$C$163,2,0)) -> 1 | B10: =IF(C10="","",VLOOKUP(C10,지역코드!$A$2:$C$163,3,0)) -> 광주 | C10: 광주 | I10: 장등저수지 | L10: 라우터 | M10: IPT-422 | P10: 장등동 산 121-6 | R10: - | S10: - | T10: 012-2517-1995 | U10: 121.147.160.193 | V10: 20.200.1.1 | W10: 80
A11: =IF(C11="","",VLOOKUP(C11,지역코드!$A$2:$C$163,2,0)) -> 1 | B11: =IF(C11="","",VLOOKUP(C11,지역코드!$A$2:$C$163,3,0)) -> 광주 | C11: 광주 | I11: " | L11: 강우 | M11: EWRAIN | P11: " | R11: 35.214634 | S11: 126.92295 | T11: " | U11: 20.200.1.1 | V11: 20.200.1.2 | W11: 4096
A12: =IF(C12="","",VLOOKUP(C12,지역코드!$A$2:$C$163,2,0)) -> 1 | B12: =IF(C12="","",VLOOKUP(C12,지역코드!$A$2:$C$163,3,0)) -> 광주 | C12: 광주 | I12: " | L12: 수위 | M12: EWWATER | P12: " | R12: 35.214671 | S12: 126.92294 | T12: " | U12: 20.200.1.1 | V12: 20.200.1.2 | W12: 4096
A13: =IF(C13="","",VLOOKUP(C13,지역코드!$A$2:$C$163,2,0)) -> 1 | B13: =IF(C13="","",VLOOKUP(C13,지역코드!$A$2:$C$163,3,0)) -> 광주 | C13: 광주 | I13: 장등저수지 | L13: 라우터 | M13: IPT-422 | P13: 장등동 산 121-6 | R13: - | S13: - | T13: 012-2517-2321 | U13: 121.147.160.193 | V13: 20.200.2.1 | W13: 80
A14: =IF(C14="","",VLOOKUP(C14,지역코드!$A$2:$C$163,2,0)) -> 1 | B14: =IF(C14="","",VLOOKUP(C14,지역코드!$A$2:$C$163,3,0)) -> 광주 | C14: 광주 | I14: "_1 | L14: 변위 | M14: EWPP | P14: " | R14: 35.214599 | S14: 126.92295 | T14: " | U14: 20.200.2.1 | V14: 20.200.2.9 | W14: 4096
A15: =IF(C15="","",VLOOKUP(C15,지역코드!$A$2:$C$163,2,0)) -> 1 | B15: =IF(C15="","",VLOOKUP(C15,지역코드!$A$2:$C$163,3,0)) -> 광주 | C15: 광주 | I15: "_2 | L15: 변위 | M15: EWPP | P15: " | R15: 35.21458 | S15: 126.9229 | T15: " | U15: 20.200.2.1 | V15: 20.200.2.9 | W15: 4096
A16: =IF(C16="","",VLOOKUP(C16,지역코드!$A$2:$C$163,2,0)) -> 1 | B16: =IF(C16="","",VLOOKUP(C16,지역코드!$A$2:$C$163,3,0)) -> 광주 | C16: 광주 | I16: 장등저수지 | L16: 예경보 | M16: EWALT | P16: 장등동 1016-1 | R16: 35.215011 | S16: 126.92957 | T16: 012-5491-3547 | V16: 211.34.105.29 | W16: 4096
A17: 부산시청 / 부산 동래구청 지하차도 침수차단 구매 설치
A18: =IF(C18="","",VLOOKUP(C18,지역코드!$A$2:$C$163,2,0)) -> 4 | B18: =IF(C18="","",VLOOKUP(C18,지역코드!$A$2:$C$163,3,0)) -> 부산 | C18: 부산
A19: 부산시청 / 부산 남구청_동천변 재난대응 조기경보시스템 수위계 제작구매
A20: =IF(C20="","",VLOOKUP(C20,지역코드!$A$2:$C$163,2,0)) -> 4 | B20: =IF(C20="","",VLOOKUP(C20,지역코드!$A$2:$C$163,3,0)) -> 부산 | C20: 부산
A21: 세종시청 / 북암천 수위센서 설치
A22: =IF(C22="","",VLOOKUP(C22,지역코드!$A$2:$C$163,2,0)) -> 5 | B22: =IF(C22="","",VLOOKUP(C22,지역코드!$A$2:$C$163,3,0)) -> 세종 | C22: 세종 | L22: 수위 | P22: 읍내리 57-2 | R22: 36.68601 | S22: 127.2009
A23: 인천시청 / 기상관측
A24: =IF(C24="","",VLOOKUP(C24,지역코드!$A$2:$C$163,2,0)) -> 7 | B24: =IF(C24="","",VLOOKUP(C24,지역코드!$A$2:$C$163,3,0)) -> 인천 | C24: 인천 | D24: " | I24: 서버 | P24: IDC6F 재난안전상황실 | V24: 101.0.116.157 | W24: 80,8021
A25: =IF(C25="","",VLOOKUP(C25,지역코드!$A$2:$C$163,2,0)) -> 7 | B25: =IF(C25="","",VLOOKUP(C25,지역코드!$A$2:$C$163,3,0)) -> 인천 | C25: 인천 | D25: " | I25: 상황판1 | P25: 본관3F 시민안전본부장실 | V25: 101.0.32.3
A26: =IF(C26="","",VLOOKUP(C26,지역코드!$A$2:$C$163,2,0)) -> 7 | B26: =IF(C26="","",VLOOKUP(C26,지역코드!$A$2:$C$163,3,0)) -> 인천 | C26: 인천 | D26: " | I26: 상황판2 | P26: 본관5F 재난예방과 | V26: 101.0.93.24
A27: =IF(C27="","",VLOOKUP(C27,지역코드!$A$2:$C$163,2,0)) -> 7 | B27: =IF(C27="","",VLOOKUP(C27,지역코드!$A$2:$C$163,3,0)) -> 인천 | C27: 인천 | D27: "
A28: =IF(C28="","",VLOOKUP(C28,지역코드!$A$2:$C$163,2,0)) -> 7 | B28: =IF(C28="","",VLOOKUP(C28,지역코드!$A$2:$C$163,3,0)) -> 인천 | C28: 인천 | D28: "
A29: 인천 남동구청 / 기상관측
A30: =IF(C30="","",VLOOKUP(C30,지역코드!$A$2:$C$163,2,0)) -> 7 | B30: =IF(C30="","",VLOOKUP(C30,지역코드!$A$2:$C$163,3,0)) -> 인천 | C30: 인천 | D30: " | I30: 서버 | P30: 남동구청 | V30: 105.5.36.28
A31: =IF(C31="","",VLOOKUP(C31,지역코드!$A$2:$C$163,2,0)) -> 7 | B31: =IF(C31="","",VLOOKUP(C31,지역코드!$A$2:$C$163,3,0)) -> 인천 | C31: 인천 | D31: " | I31: 남동구청 | L31: 강우 | M31: EWRAIN | P31: 만수동 1008 | R31: 37.44735 | S31: 126.7315 | V31: 101.5.36.91 | W31: 4096
A32: =IF(C32="","",VLOOKUP(C32,지역코드!$A$2:$C$163,2,0)) -> 7 | B32: =IF(C32="","",VLOOKUP(C32,지역코드!$A$2:$C$163,3,0)) -> 인천 | C32: 인천 | D32: " | I32: 구월3동 | L32: 강우 | M32: EWRAIN | P32: 구월동 1098-7 | R32: 37.4527 | S32: 126.6969 | V32: 101.5.220.112 | W32: 4096
A33: =IF(C33="","",VLOOKUP(C33,지역코드!$A$2:$C$163,2,0)) -> 7 | B33: =IF(C33="","",VLOOKUP(C33,지역코드!$A$2:$C$163,3,0)) -> 인천 | C33: 인천 | D33: " | I33: 논현1동 | L33: 강우 | M33: EWRAIN | P33: 논현동 603-5 | R33: 37.40569 | S33: 126.7293 | V33: 101.5.229.81 | W33: 4096
A34: =IF(C34="","",VLOOKUP(C34,지역코드!$A$2:$C$163,2,0)) -> 7 | B34: =IF(C34="","",VLOOKUP(C34,지역코드!$A$2:$C$163,3,0)) -> 인천 | C34: 인천 | D34: " | I34: 공단소방서 | L34: 라우터 | M34: IPR-422 | P34: 고잔동 633 | R34: 37.40813 | S34: 126.693 | T34: 012-2560-6592 | V34: 20.137.16.1 | W34: 80
A35: =IF(C35="","",VLOOKUP(C35,지역코드!$A$2:$C$163,2,0)) -> 7 | B35: =IF(C35="","",VLOOKUP(C35,지역코드!$A$2:$C$163,3,0)) -> 인천 | C35: 인천 | D35: " | I35: " | L35: 강우 | P35: " | R35: " | S35: " | T35: " | U35: 20.137.16.1 | V35: 20.137.16.2 | W35: 4096
A36: 인천 남동구청 / 수위관측
A37: =IF(C37="","",VLOOKUP(C37,지역코드!$A$2:$C$163,2,0)) -> 7 | B37: =IF(C37="","",VLOOKUP(C37,지역코드!$A$2:$C$163,3,0)) -> 인천 | C37: 인천 | D37: " | I37: 서버 | P37: 남동구청 | V37: 192.168.50.102
A38: =IF(C38="","",VLOOKUP(C38,지역코드!$A$2:$C$163,2,0)) -> 7 | B38: =IF(C38="","",VLOOKUP(C38,지역코드!$A$2:$C$163,3,0)) -> 인천 | C38: 인천 | D38: " | I38: 서버 | L38: 라우터 | M38: IPR-400W | P38: " | T38: 012-2297-8896
A39: =IF(C39="","",VLOOKUP(C39,지역코드!$A$2:$C$163,2,0)) -> 7 | B39: =IF(C39="","",VLOOKUP(C39,지역코드!$A$2:$C$163,3,0)) -> 인천 | C39: 인천 | D39: " | I39: WCDMA모듈 | L39: WCDMA | M39: TX-700 | P39: " | T39: 012-5446-2254
A40: =IF(C40="","",VLOOKUP(C40,지역코드!$A$2:$C$163,2,0)) -> 7 | B40: =IF(C40="","",VLOOKUP(C40,지역코드!$A$2:$C$163,3,0)) -> 인천 | C40: 인천 | D40: " | I40: 논현포대 | L40: 수위 | M40: KMACBOW | R40: 37.403889 | S40: 126.70583 | V40: 10.0.1.2
A41: =IF(C41="","",VLOOKUP(C41,지역코드!$A$2:$C$163,2,0)) -> 7 | B41: =IF(C41="","",VLOOKUP(C41,지역코드!$A$2:$C$163,3,0)) -> 인천 | C41: 인천 | D41: " | I41: "_예경보 | L41: 예경보 | M41: EWALT | R41: 37.403889 | S41: 126.70593 | T41: 012-5446-2255
A42: =IF(C42="","",VLOOKUP(C42,지역코드!$A$2:$C$163,2,0)) -> 7 | B42: =IF(C42="","",VLOOKUP(C42,지역코드!$A$2:$C$163,3,0)) -> 인천 | C42: 인천 | D42: " | I42: 승기천 | L42: 수위 | M42: KMACBOW | R42: 37.411389 | S42: 126.68972 | V42: 10.0.2.2
...

Sheet NDMS정보
C5: 강원 | D5: 원주시 | E5: 무진 | F5: 재해위험 개선지구 | G5: 45232
C6: 강원 | D6: 철원군 | E6: 도창 | F6: 재해위험 개선지구 | G6: 45216
C7: 강원 | D7: 철원군 | E7: 이길 | F7: 재해위험 개선지구 | G7: 45216
C8: 강원 | D8: 철원군 | E8: 청양 | F8: 재해위험 개선지구 | G8: 45216
C9: 강원 | D9: 영월군 | E9: 창원2 | F9: 급경사지 | G9: 45219
C10: 강원 | D10: 영월군 | E10: 구래3 | F10: 급경사지 | G10: 45219
C11: 강원 | D11: 영월군 | E11: 법흥2 | F11: 급경사지 | G11: 45219
C12: 강원 | D12: 강릉 | E12: 남대천둔치주차장 | F12: 둔치주차장 차량 침수위험 신속알림 시스템
C13: 강원 | D13: 동해시 | E13: 전천 | F13: 둔치주차장 차량 침수위험 신속알림 시스템
C14: 강원 | D14: 횡성군 | E14: 내지지구 | F14: 하천구역 출입 자동차단 시스템
C15: 강원 | D15: 정선군 | E15: 선명A | F15: 조기경보시스템(급경사지)
C16: 강원 | D16: 정선군 | E16: 운치3 | F16: 조기경보시스템(급경사지)
C17: 강원 | D17: 정선군 | E17: 덕송3 | F17: 조기경보시스템(급경사지)
C18: 경기 | D18: 안성시 | E18: 안성천 둔치 1 주차장 | F18: 둔치주차장 차량 침수위험 신속알림 시스템
C19: 경기 | D19: 안성시 | E19: 안성천 둔치 2 주차장 | F19: 둔치주차장 차량 침수위험 신속알림 시스템
C20: 경기 | D20: 안성시 | E20: 안성천 둔치 3 주차장 | F20: 둔치주차장 차량 침수위험 신속알림 시스템
C21: 경기 | D21: 안성시 | E21: 청미천 둔치주차장 | F21: 둔치주차장 차량 침수위험 신속알림 시스템
C22: 경남 | D22: 합천군 | E22: 영창주공 | F22: 둔치주차장 차량 침수위험 신속알림 시스템
C23: 경북 | D23: 영천시 | E23: 가천 | F23: 재해위험 개선지구
... C75: 충북 | D75: 증평군 | E75: 보강천 둔치주차장 | F75: 둔치주차장 차량 침수위험 신속알림 시스템
I733: 항골계곡 상류 | P733: 북평리 876 | V733: 152.99.171.181
I734: " | P734: " | T734: "
I735: 항골계곡 중류 | L735: 예경보 | M735: EWALT | P735: 북평리 산136-4 | V735: 012-4214-9231 | W735: 211.34.105.29 | X735: 4096
I736: 북평5리 마을회관 | L736: 마을방송 | M736: EWALT | P736: 북평리 319-29 | V736: 012-3328-6318 | W736: 211.34.105.29 | X736: 4096
I737: 덕산1교 | L737: 예경보 | M737: EWALT | P737: 덕우리 산 17-7 | V737: 012-4214-9230 | W737: 211.34.105.29 | X737: 4096
I738: 덕산2교 | L738: 예경보 | M738: EWALT | P738: 덕우리 산 17-9 | V738: 012-4214-9234 | W738: 211.34.105.29 | X738: 4096
I739: 덕산3교 | M739: EWALT | P739: 덕우리 239-3 | V739: 012-4214-9232 | W739: 211.34.105.29 | X739: 4096
I740: 덕산기계곡 | M740: EWALT | P740: 덕우리 233 | V740: 012-4214-9233 | W740: 211.34.105.29 | X740: 4096
V1068: 20.160.17.1

Sheet VPN 정보
C5: 양구군청 | F5: Axgate 80D | H5: 임대
C6: 1
C7: 2
C8: 3
C9: 4
C10: 5
C11: 6
C12: 7
C13: 8
C14: 9
C15: 옥천 | F15: Axgate 300S | H15: 임대
C16: 1
C17: 2
C18: 3
C19: 4
C20: 5
C21: 6
C22: 7
C23: 8
C24: 9
C25: 10
C26: 11
C27: 12
... C51: 36
C52: 부여 | F52: Axgate 80D | H52: 임대
C53: 1
C54: 2
C55: 3
C56: 4
C57: 5
C58: 6
C59: 7
C60: 공주 | F60: Axgate 80D | H60: 임대
C61: 1
C62: 2
C63: 3
C64: 4
C65: 5
C66: 6
C67: 7
...

Sheet 제품사양
B6: OS 설치일 | E6: 약칭 | F6: 제조사 | G6: 모델명 | H6: OS | I6: CPU | J6: RAM | K6: HDD | L6: HDD(C:) | M6: HDD(D:) | N6: HDD(E:) | O6: XAMPP | P6: Apache | Q6: PHP | R6: MySQL | T6: IP | U6: IP2 | V6: G/W
C7: 증평 | E7: HPE DL20 | F7: HPE | G7: ProLiant DL20 Gen10 | H7: Windows Server 2019 Standard | I7: Xeon E-2224@3.4GHz(1Socket, 4Core, 4Thread) | J7: 16GB | L7: 1TB | M7: 1TB | O7: 3.3.0 | P7: 2.4.53 | Q7: 7.4.28 | R7: 10.4.24 | T7: 20.200.0.100 | V7: 20.200.0.1 / 24
C9: 진안 | E9: DELL R740 | F9: DELL | G9: PowerEdge R740 | H9: Windwos Server 2019 Standard | I9: Xeon Gold 5222@3.8GHz(2Socket, 8Core, 16Thread) | J9: 32GB | K9: DELL PERC H750 2TB | L9: 1TB | M9: 1TB | O9: 3.3.0 | P9: 2.4.53 | Q9: 8.1.4 | R9: 10.4.24
C11: 고창 | E11: DELL R740 | F11: DELL | G11: PowerEdge R740 | H11: Windwos Server 2019 Standard | I11: Xeon Gold 5222@3.8GHz(2Socket, 8Core, 16Thread) | J11: 32GB | K11: DELL PERC H750 2TB | L11: 1TB | M11: 1TB | O11: 3.2.4 | P11: 2.4.46 | Q11: 7.4.11 | R11: 10.4.14 | T11: 20.130.0.100 | V11: 20.130.0.1 / 24
C13: 부여 | E13: HPE DL360 | F13: HPE | G13: ProLiant DL360 Gen10 | H13: Windows Server 2019 Standard | I13: Xeon Silver 4210R@2.4GHz(1Socket, 10Core, 20Thread) | J13: 16GB | K13: SAS 1.2TB *2, RAID1 | L13: 300 | M13: 800
C15: 공주 | E15: DELL R540 | F15: DELL | G15: PowerEdge R540 | H15: Windows Server 2019 Standard | I15: Xeon Silver 4210R@2.4GHz(1Socket, 10Core, 20Thread) | J15: 16GB | K15: DELL PERC H730P, RAID1 | L15: 1TB | O15: 3.2.4 | P15: 2.4.46 | Q15: 7.4.11 | R15: 10.4.14 | T15: 210.123.195.125 | V15: 210.123.195.126 / 28
C17: 음성 | E17: HPE DL20 | F17: HPE | G17: ProLiant DL20 Gen10 | H17: Windows Server 2019 Standard | I17: Xeon E-2236@3.4Ghz(1Socket, 6Core, 12Thread) | J17: 64GB | L17: 1TB | O17: 3.2.4 | P17: 2.4.46 | Q17: 7.4.11 | R17: 10.4.14
C19: 김제 | D19: 통합발령 | E19: DELL R740 | F19: DELL | G19: PowerEdge R740 | H19: Windows Server 2019 Standard | I19: Xeon Gold 5222@3.8GHz(2Socket, 8Core, 16Thread) | J19: 32GB | O19: 3.3.0 | P19: 2.4.53 | Q19: 7.4.29 | R19: 10.4.24
C20: " | D20: 둔치관측 | E20: DELL R740 | F20: DELL | G20: PowerEdge R740 | H20: Windows Server 2019 Standard | I20: Xeon Gold 5222@3.8GHz(2Socket, 8Core, 16Thread) | J20: 32GB
C22: 무안 | E22: HPE DL20 | F22: HPE | G22: ProLiant DL20 Gen10 | H22: Windows Server 2019 Standard | I22: Xeon E-2224@3.4GHz(1Socket, 4Core, 4Thread) | J22: 16GB | L22: 500GB | M22: 500GB | O22: 3.3.0 | P22: 2.4.53 | Q22: 8.1.4 | R22: 10.4.24 | T22: 20.170.0.100 | V22: 20.170.0.1 / 24
C24: 횡성 | D24: 침수 | E24: DELL R740 | F24: DELL | G24: PowerEdge R740 | H24: Windows Server 2019 Standard | I24: Xeon Silver 4215@2.5GHz(2Socket, 16Core, 32Thread) | J24: 32GB | K24: DELL PERC H730P, 280GB? | L24: 60GB | M24: 215GB | O24: APM7 | P24: 2.2.14 | Q24: 5.2.12 | R24: 5.1.41 | T24: 152.99.149.182 | V24: 152.99.149.254 / 25
C25: " | D25: DB중계 | E25: 용산800 | F25: ASUS | H25: Windows Server 2022 Standard | I25: Xeon E-2124@3.3GHz(1Socket, 4Core, 4Thread) | J25: 16GB | L25: 500GB | M25: 1TB | N25: 1TB | O25: 3.3.0 | P25: 2.4.54 | Q25: 7.4.33 | R25: 10.4.27 | T25: 106.9.91.204 | V25: 106.9.91.254 / 24
B27: 2020.05.14 | C27: 춘천 | D27: 침수 | E27: DELL R740 | F27: DELL | G27: PowerEdge R740 | H27: Windws Server 2019 Standard | I27: Xeon Silver 4215@2.5Ghz(2Socket, 16Core, 32Thread) | J27: 32GB | K27: DELL PERC H730P, 280GB? | L27: 150GB | M27: 126 | O27: APM7 | P27: 2.2.14 | Q27: 5.2.12 | R27: 5.1.41 | T27: 152.99.147.59 | V27: 152.99.147.1 / 25
C29: 강릉 | D29: 침수 | T29: 20.150.0.100 | V29: 20.150.0.1 / 24
B31: 2020.05.20 | C31: 동해 | D31: 침수 | E31: DELL R740 | F31: DELL | G31: PowerEdge R740 | H31: Windws Server 2019 Standard | I31: Xeon Silver 4215@2.5Ghz(2Socket, 16Core, 32Thread) | J31: 32GB | K31: DELL PERC H730P, 280GB? | O31: APM7 | P31: 2.2.14 | Q31: 5.2.12 | R31: 5.1.41 | T31: 152.99.144.55 | V31: 152.99.144.1 / 24
T32: 172.16.77.14 | V32: 172.16.0.1 / 16
C33: 동해 | D33: DB중계 | E33: DELL R540 | F33: DELL | G33: PowerEdge R540 | H33: Windws Server 2019 Standard | I33: Xeon Silver 4210R@2.4Ghz(1Socket, 10Core, 20Thread) | J33: 16GB | L33: 1TB | M33: - | N33: - | O33: - | P33: - | Q33: - | R33: - | T33: 106.4.36.139 | V33: 106.4.36.254 / 25
B34: 2020.05.14? | C34: 삼척 | D34: 침수 | E34: DELL R740 | F34: DELL | G34: PowerEdge R740 | H34: Windws Server 2019 Standard | I34: Xeon Silver 4215@2.5Ghz(2Socket, 16Core, 32Thread) | J34: 32GB | O34: APM7 | P34: 2.2.14 | Q34: 5.2.12 | R34: 5.1.41 | T34: 152.99.147.59
B35: 2018.05.06 | C35: 삼척 | D35: 기상 | E35: DELL R640 | F35: DELL | G35: PowerEdge R640 | H35: Windows Server 2016 Standard | I35: Xeon Gold 5122@3.6GHz(2Socket, 8Core, 16Thread) | J35: 16GB | K35: DELL PERC H730P, 280GB? | L35: 280GB | O35: APM7 | P35: 2.2.14 | Q35: 5.2.12 | R35: 5.1.41 | T35: 106.7.28.45 | V35: 106.7.28.254 / 24
T36: 172.16.79.45 | V36: 172.16.0.1 / 16
B37: 2022.02.08 | C37: 원주 | D37: 급경사지 | E37: DELL R740 | F37: DELL | G37: PowerEdge R740 | H37: Windows Server 2019 Standard | I37: Xeon Gold 5222@3.8GHz(2Socket, 8Core, 16Thread) | J37: 32GB | K37: DELL PERC H750, 2TB? | L37: 1TB | M37: 1TB | O37: 3.3.0 | P37: 2.4.53 | Q37: 7.4.28 | R37: 10.4.24 | T37: 20.200.0.100 | V37: 20.200.0.1 / 24
B38: 2022.02.08 | C38: " | D38: DB중계 | E38: DELL R740 | F38: DELL | G38: PowerEdge R740 | H38: Windows Server 2019 Standard | I38: Xeon Gold 5222@3.8GHz(2Socket, 8Core, 16Thread) | J38: 32GB | K38: DELL PERC H750, 2TB? | L38: 1TB | M38: 1TB | O38: 3.3.0 | R38: 10.4.24 | T38: 106.2.10.191 | V38: 106.2.10.50 / 24
B39: 2018.06.12 | C39: " | D39: 기상 | E39: DELL R530 | F39: DELL | G39: PowerEdge R530 | H39: Windows Server 2012 R2 Standard | I39: Xeon E5 2609 v4@1.7Ghz(1Socket, 8Core, 8Thread) | J39: 8GB | L39: 1TB | M39: X | O39: IIS
B40: 2020.05.14? | C40: " | D40: 침수 | E40: DELL R740 | F40: DELL | G40: PowerEdge R740 | H40: Windows Server 2019 Standard | I40: Xeon Silver 4215@2.5GHz(2Socket, 16Core, 32Thread) | J40: 32GB | T40: 152.99.142.60 | V40: 152.99.142.1 / 24
C42: 영월 | D42: 침수 | E42: Precision 3630 | F42: DELL | G42: Precision 3630 Tower | H42: Windows 10 Pro | I42: Core i5-9500(1Socket, 6Core, 6Thread) | J42: 16GB
B44: 2022.10.21 | C44: 영월 | D44: 급경사지 | E44: DELL R740 | F44: DELL | G44: PowerEdge R740 | H44: Windows Server 2019 Standard | I44: Xeon Gold 5222@3.8GHz(2Socket, 8Core, 16Thread) | J44: 32GB | K44: DELL PERC H750, 2TB? | L44: 1TB | M44: RAID | O44: 3.3.0 | P44: 2.4.53 | Q44: 7.4.29 | R44: 10.4.24 | T44: 20.200.0.100 | V44: 20.200.0.1 / 24
C45: " | D45: DB중계 | E45: DELL R740 | F45: DELL | G45: PowerEdge R740 | H45: Windows Server 2019 Standard | I45: Xeon Gold 5222@3.8GHz(2Socket, 8Core, 16Thread) | J45: 32GB | K45: DELL PERC H750, 2TB? | L45: 1TB | M45: RAID | O45: 3.3.0 | R45: 10.4.24 | T45: 106.10.45.32 | V45: 106.10.45.1 / 24
D46: 수집서버 | E46: DELL R740 | F46: DELL | G46: PowerEdge R740 | H46: Windows Server 2019 Standard | I46: Xeon Gold 5222@3.8GHz(2Socket, 8Core, 16Thread) | J46: 32GB | K46: DELL PERC H750, 2TB? | L46: 2TB | O46: X | R46: 10.3 | T46: 20.200.0.101
D47: 백업서버 | E47: ?? | T47: 20.200.0.102
B49: 2022.06.20 | C49: 철원 | D49: 관측서버 | E49: HPE DL20 | F49: HPE | G49: ProLiant DL20 Gen10 | H49: Windows Server 2019 Standard | I49: Xeon E-2224@3.4GHz(1Socket, 4Core, 4Thread) | J49: 16GB | K49: 1TB | L49: 465GB | M49: 465GB | O49: 3.3.0 | P49: 2.4.53 | Q49: 7.4.29 | R49: 10.4.24 | T49: 20.200.0.100 | V49: 20.200.0.1 / 24
C50: " | D50: DB중계 | E50: HPE DL20 | F50: HPE | G50: ProLiant DL20 Gen10 | H50: Windows Server 2019 Standard | I50: Xeon E-2224@3.4GHz(1Socket, 4Core, 4Thread) | J50: 16GB | K50: 1TB | O50: 3.3.0 | R50: 10.4.24 | T50: 106.13.2.149 | V50: 106.13.2.1 / 24
C52: 정선 | D52: 둔치관측
B53: 2021.08.25 | C53: " | D53: DB중계 | E53: DELL R740 | F53: DELL | G53: PowerEdge R740 | H53: Windows Server 2019 Standard | I53: Xeon Gold 5222@3.8GHz(2Socket, 8Core, 16Thread) | J53: 32GB | K53: DELL PERC H740P, 1TB? | L53: 1TB | M53: x | T53: 106.12.12.142 | V53: 106.12.12.2 / 24
C54: " | D54: 관측서버 | H54: Windows Server 2019 Standard | O54: 3.2.4 | P54: 2.4.46 | Q54: 7.4.33 | R54: 10.4.14 | T54: 152.99.171.182
C57: 합천 | D57: 둔치관측 | E57: DELL R740 | F57: DELL | G57: PowerEdge R740 | H57: Windows Server 2019 Standard | I57: Xeon Gold 5222@3.8Ghz(2Socket, 8Core, 16Thread) | J57: 32GB | L57: 1TB | M57: x | O57: 3.2.4 | P57: 2.4.46 | Q57: 7.4.33 | R57: 10.4.14 | T57: 27.101.90.53 20.110.0.100 | V57: 27.101.90.126 / 25 20.110.0.1 / 24
B59: 2018.12.17 | C59: 안성 | D59: 적설 | E59: DELL R430 | F59: DELL | G59: PowerEdge R430 | H59: Windows Server 2012 R2 Standard | I59: Xeon E5-2620v4@2.1GHz(1Socket, 8Core, 16Thread) | J59: 16GB | L59: 1TB | M59: x | O59: APM7 | P59: 2.2.14 | Q59: 5.2.12 | R59: 5.1.41 | T59: 105.30.7.244 172.16.79.130 | V59: 105.30.7.254 / 24 172.16.0.1 / 16
C60: 안성 | D60: 수위 | E60: DELL R540 | F60: DELL | G60: PowerEdge R540 | H60: Windows Server 2019 Standard | I60: Xeon 4210R@2.4GHz(1Socket, 10Core, 20Thread) | J60: 16GB | O60: 3.2.4 | P60: 2.4.46 | Q60: 7.4.11 | R60: 10.4.14 | T60: 20.160.0.100 | V60: 20.160.0.1 / 24
B61: "2023.06 | C61: 안성 | D61: 둔치관측 | E61: HPE DL20 | F61: HPE | G61: DL20 | H61: Windows Server 2019 Standard | I61: Xeon E-2224@3.4GHz(1Socket, 4Core, 4Thread) | J61: 32GB | O61: 3.3.0 | P61: 2.4.54 | Q61: 7.4.33 | R61: 10.4.27 | T61: 27.101.130.122 | V61: 27.101.130.1 / 24
T62: 20.200.0.100 | V62: 20.200.0.1 / 24
B63: 2020.05.19 | C63: 홍천 | D63: 침수 | E63: DELL R740 | F63: DELL | G63: PowerEdge R740 | H63: Windows Server 2019 Standard | I63: Xeon Silver 4215@2.5GHz(2Socket, 16Core, 32Thread) | J63: 32GB | L63: 60GB | M63: 215GB | O63: APM7 | P63: 2.2.14 | Q63: 5.2.12 | R63: 5.1.41 | T63: 152.99.148.155 172.16.79.202 | V63: 152.99.148.1 / 24 172.16.255.254 / 16 | XFD63: s079sv0202
...

Sheet 계정정보
C8: Administrator / win2019! | K8: 사용자 구분 | M8: 기존시스템 | P8: 변경할 시스템 | T8: 비고
M9: 계정 | N9: 기상/침수/예경보 | P9: 기상관측시스템 | Q9: 침수차단시스템 | R9: 예경보시스템 | S9: 조기예경보시스템
C10: 구매처 | K10: 관리용 | L10: root | M10: ID | N10: WeatherSI | P10: WBWeather | Q10: WBFlood | R10: WBAlert | S10: WBEarly | T10: 시스템별 계정 구분으로 보안 강화
C11: [이름] 변영근 대표(와이케이시스템즈:서버) | M11: Pw | N11: @weathersi# | P11: #wb@weather! | Q11: #woobo@flood! | R11: #wbsys@alert! | S11: #woobosys@early!
C12: [휴대전화] 010-8283-1494 | M12: 권한 | N12: 전체권한 | P12: 전체 권한 | Q12: 전체 권한 | R12: 전체 권한 | S12: 전체 권한
C13: [개인] admin@yksys.co.kr | K13: 시스템용 | L13: user1 | M13: ID | N13: X | P13: userWooboWeb | T13: 웹용 계정
M14: Pw | P14: wooboWeb!@
M15: 권한 | P15: select, update, delete, insert
B16: 씨엔에스 | C16: admin / 1234admin / 1234admin# / admin123! | D16: 라우터 WEB | K16: 유지관리용 | L16: user2 | M16: ID | N16: X | P16: userWoobo | T16: 서버에서 DB 접속시 사용
B17: 아이피로드NMS | C17: woobosys123 | D17: http://nms.iproad.co.kr/ipr-400/w_login | E17: woobosys123!! | M17: Pw | P17: @woobo#
B18: 아이피로드 | C18: admin / admin6622 | D18: 라우터 WEB | M18: 권한 | P18: select, update
B19: 아이피로드 | C19: root / 4286622 | D19: 라우터 WEB | K19: 제휴업체 | L19: user3 | M19: ID | N19: guestWt | P19: userXXX | T19: xxx - 업체명 사용
B20: 넥스파 | C20: Administrator / nexpa1234 | D20: mstsc | M20: Pw | N20: guestWt | P20: XXX
B21: 컴텔 | C21: comtel | D21: 전광판 VNC (UltraVNC Viewer) | E21: comtel | F21: C:\SignBoard\BoardCTRL\Image | M21: 권한 | N21: Select | P21: 필요 테이블 Select
B22: 카카오지도 | C22: woobosys4781@naver.com / wb7974781 | D22: http://dapi.kakao.com | E22: f4592e97c349ab41d02ff73bd314a201
B23: 문자박사 | C23: junghane / Woobosys4781! /5361 | D23: https://www.munja123.com
B24: OPENAPI | C24: woobolab@woobosys.com / Woobosys4781! | D24: VE5IF8GtcZNcnSpkq1sygdHeIEIhixMY4dvRdZ0XNH1bj3BFF0KaVcDGwb63jc5CFpy31R71H6R3YzYRVcNrGA%3D%3D
B25: 기상청API허브 | C25: woobolab@woobosys.com / Woobosys4781! | D25: BlqTenoZQCKak3p6GUAixQ

Sheet 지역코드
A1: JHName | B1: JHACode | C1: JHDoName
A2: 서울 | B2: 0 | C2: 서울 | F2: 구분코드
A3: 광주 | B3: 1 | C3: 광주 | F3: 하천(0)
A4: 대구 | B4: 2 | C4: 대구 | F4: 내수(1)
A5: 대전 | B5: 3 | C5: 대전 | F5: 해일(2)
A6: 부산 | B6: 4 | C6: 부산 | F6: 저수지(3)
A7: 세종 | B7: 5 | C7: 세종 | F7: 급경사지(4)
A8: 울산 | B8: 6 | C8: 울산 | F8: 교량(5)
A9: 인천 | B9: 7 | C9: 인천 | F9: 옹벽(6)
A10: 서귀포 | B10: 8 | C10: 제주 | F10: 건축물(7)
A11: 제주 | B11: 9 | C11: 제주 | F11: 기타(Z)
A12: 강릉 | B12: 10 | C12: 강원
A13: 고성 | B13: 11 | C13: 강원
A14: 동해 | B14: 12 | C14: 강원 | E14: 재해위험지구 | F14: https://www.safekorea.go.kr/idsiSFK/neo/sfk/cs/sfc/fcl/riskUserList.html?menuSeq=314
A15: 삼척 | B15: 13 | C15: 강원
A16: 속초 | B16: 14 | C16: 강원
A17: 양구 | B17: 15 | C17: 강원
A18: 양양 | B18: 16 | C18: 강원
A19: 영월 | B19: 17 | C19: 강원
A20: 원주 | B20: 18 | C20: 강원
A21: 인제 | B21: 19 | C21: 강원
A22: 정선 | B22: 20 | C22: 강원
A23: 철원 | B23: 21 | C23: 강원
A24: 춘천 | B24: 22 | C24: 강원
A25: 태백 | B25: 23 | C25: 강원
A26: 평창 | B26: 24 | C26: 강원
... A163: 충주 | B163: 161 | C163: 충북

Sheet 시스템현황파악
J2: c:\APM_Setup\Server\Apache\bin\httpd.exe -v && c:\APM_Setup\Server\MySQL5\bin\mysqld.exe --version && c:\APM_Setup\Server\PHP5\php.exe --version
B4: 구분 | C4: 시스템 명칭 | D4: 공인 IP | E4: 로컬 IP | F4: OS | G4: 웹페이지 | H4: DB구조 | I4: 서비스 | J4: Apache | K4: MySQL | L4: PHP | M4: 수집 | N4: 방송 | O4: 문자 | P4: 전광판 | Q4: 차단기 | R4: 기상 | S4: 자동실행 | T4: NMS
B10: 우보재난시스템 시스템 현황 파악
B13: 구분 | C13: 시스템 명칭 | D13: 공인 IP | E13: 로컬 IP | F13: OS | G13: 웹페이지 | H13: DB구조 | I13: 서비스 | J13: Apache | K13: MySQL | L13: PHP | M13: 수집 | N13: 방송 | O13: 문자 | P13: 전광판 | Q13: 차단기 | R13: 기상 | S13: 자동실행 | T13: NMS
B14: 유지보수대상 시스템 | C14: 강원_동해_둔치주차_관측서버 | D14: 152.99.144.55 | E14: 152.99.144.55 | F14: Server 2019 1809 | G14: 지능형통합관제시스템 | H14: EW | I14: XAMPP 3.3.0 | J14: 2.4.58 | K14: 10.4.32 | L14: 8.2.12 | M14: 1.6.3 | N14: 1.6.3 | O14: 1.6.3 | P14: 1.6.3 | Q14: 1.6.3 | R14: 1.6.3 | S14: 1.6.3 | T14: 주소입력필요
C15: 강원_삼척_기상서버 | D15: 211.253.82.243 | E15: 106.7.28.45 | F15: Server 2016 1607 | G15: 기상 관측 시스템 | H15: JH | I15: APM | J15: 2.2.14 | K15: 5.1.41 | L15: 5.2.12 | M15: 필요 CB | N15: - | O15: - | P15: - | Q15: - | U15: 기상청 AWS
C16: 강원_원주_수위관측_서버 | D16: 211.253.82.243 | E16: 106.2.103.163 | F16: Server 2012 R2 | G16: 기상 관측 시스템 | H16: JH | I16: IIS | J16: IIS 8.5 | K16: 10.4.27 | L16: ASP | M16: 1.6.3 | N16: - | O16: - | P16: - | Q16: - | R16: 1.6.3 | S16: 1.6.3 | T16: 주소입력필요
C17: 강원_정선_통합관제_관측서버 | D17: 152.99.171.182 | E17: 152.99.171.182 | F17: Server 2019 1809 | G17: 지능형 통합관제시스템 | H17: EW | I17: XAMPP 3.2.4 | J17: 2.4.46 | K17: 10.4.14 | L17: 7.4.33 | M17: 1.6.1 | N17: 1.6.1 | O17: 1.6.1 | P17: 1.7.0 | Q17: 1.7.0 | R17: 1.6.3 | S17: 1.6.3 | T17: 주소입력필요
C18: 강원_정선_서버 | D18: 211.253.82.243 | E18: 106.12.12.133 | F18: Server 2012 R2 | G18: 재난예경보 시스템 | H18: JH | I18: XAMPP 3.2.4 | J18: 2.4.46 | K18: 10.4.14 | L18: 7.4.11 | M18: 불필요 | N18: - | O18: - | P18: - | Q18: - | U18: 철거예정
C19: 강원_철원_기상관측_서버 | D19: 211.253.82.235 | E19: 106.13.5.44 | F19: Server 2012 R2 | G19: 기상 관측 시스템 | H19: JH | I19: XAMPP 3.2.4 | J19: 2.4.46 | K19: 10.4.14 | L19: 7.4.11 | M19: 완료 | N19: - | O19: - | P19: - | Q19: - | U19: 철거됨
C20: 강원_철원_조기경보_관측서버 | D20: 152.99.172.86 | E20: 20.200.0.100 | F20: Server 2019 1809 | G20: 조기예경보 시스템 | H20: EW | I20: XAMPP 3.3.0 | J20: 2.4.53 | K20: 10.4.24 | L20: 7.4.29 | M20: 1.6.3 | N20: 1.6.3 | O20: 1.6.3 | P20: 1.6.3 | Q20: - | R20: 1.6.3 | S20: 1.6.3 | T20: 완료 | U20: 통계, NDMS
C21: 강원_양구_조기경보 | D21: 221.144.206.176 | E21: 192.168.0.110 | F21: Server 2019 | G21: -(부린) | H21: EQP | I21: - | J21: - | K21: 10.4.19 | L21: - | M21: 필요t-eqp | N21: 필요 | O21: 필요 | P21: - | Q21: - | R21: -
A22: Rust-MS | C22: 인천_연수구청 | F22: Server 2012 R2 | G22: 기상관측시스템 | H22: JH | I22: 서버교체예정 | M22: 보류 | N22: - | O22: - | P22: - | Q22: - | U22: 교체예정
C23: 인천_남동구청_기상관측_서버 | D23: 211.253.98.34 | E23: 101.5.36.28 | F23: 10 Pro 21H2 | G23: 기상실황판 | H23: EW | I23: IIS | J23: IIS 10.0 | K23: 10.4.14 | L23: ASP | M23: 1.6.3 | N23: - | O23: - | P23: - | Q23: - | R23: - | S23: 1.6.3 | T23: 완료
C24: 인천_남동구청_수위관측_서버 | D24: 223.171.48.228 | E24: 192.168.50.102 | F24: Server 2022 21H2 | G24: 지능형 통합관제시스템 | H24: EW | I24: XAMPP | J24: 3.3.0 | M24: 1.6.3 | N24: 1.6.3 | O24: 1.6.3 | P24: - | Q24: - | R24: 1.6.3 | S24: 1.6.3 | T24: 완료
C25: 인천_부평_서버 | D25: 211.253.98.18 | E25: 101.6.63.20 | F25: Server 2012 R2 | G25: 기상실황(관광안내도) | H25: ETC(aws) | I25: IIS | J25: IIS 8.5 | K25: 5.7.7 | L25: ASP | M25: 필요 | N25: - | O25: - | P25: - | Q25: -
C26: 인천_중구_서버 | D26: 211.253.98.18 | E26: 101.1.83.109 | F26: 10 Pro 22H2 | G26: 기상 관측 시스템 | H26: JH | I26: APM | J26: 2.2.14 | K26: 5.1.41 | L26: 5.2.12 | M26: 1.6.1 | N26: - | O26: - | P26: - | Q26: -
C27: 충남_서산_서버 | D27: 210.95.187.137 | E27: 108.5.31.200 | F27: Server 2012 R2 | G27: 기상 관측 시스템 | H27: JH | I27: APM | J27: 2.2.14 | K27: 5.1.41 | L27: 5.2.12 | M27: 완료 | N27: - | O27: - | P27: - | Q27: -
C28: 충남_서천_기상관측_관측서버 | D28: 210.95.187.175 | E28: 108.10.60.205 | F28: Server 2016 1607 | G28: 기상 관측 시스템 | H28: EW | I28: AutoSet9 | J28: 2.4.10 | K28: 10.4.27 | L28: 5.6.0 | M28: 필요CB | N28: - | O28: - | P28: - | Q28: -
C29: 충남_예산_둔치주차_관측서버 | D29: 27.101.63.68 | E29: 20.100.0.100 | F29: Server 2019 1809 | G29: 둔치주차장 침수차단시스템 | H29: EW | I29: XAMPP 3.2.4 | J29: 2.4.46 | K29: 10.4.14 | L29: 7.4.33 | M29: 1.6.3 | N29: 웹 | O29: 웹 | P29: 1.6.3 | Q29: 1.6.3 | R29: 1.6.3 | S29: 1.6.3 | T29: 완료 | U29: 통계, 임계치, 경보발령
C30: 충남_태안_서버 | D30: 210.95.187.179 | E30: 108.14.25.26 | F30: Server 2016 1607 | G30: 기상 관측 시스템 | H30: JH | I30: APM | J30: 2.2.14 | K30: 5.1.41 | L30: 5.2.12 | M30: 1.6.1 | N30: - | O30: - | P30: - | Q30: - | U30: 도청,KMA데이터, 임계치문자, 표출용데이터, 강우1분수집
C31: 서울_동대문구 | E31: 98.6.62.21 | F31: Server 2019 1809 | G31: 조기예경보 시스템 | H31: EW | I31: XAMPP 3.2.4 | J31: 2.4.46 | K31: 10.4.14 | L31: 7.4.11 | M31: 완료 | N31: - | O31: 완료 | P31: - | Q31: - | T31: 접속불가
M32: 13/17완료 | N32: 완료 | O32: 완료 | P32: 완료 | Q32: 완료
B34: 구분 | C34: 시스템 명칭 | D34: 공인 IP | E34: 로컬 IP | F34: OS | G34: 웹페이지 | H34: DB구조 | I34: 서비스 | J34: Apache | K34: MySQL | L34: PHP | M34: 수집 | N34: 방송 | O34: 문자 | P34: 전광판 | Q34: 차단기 | R34: 기상 | S34: 자동실행 | T34: NMS
B35: 유지보수 미계약 관심지역 | C35: 경기_안성_수위 | E35: 20.160.0.100 | F35: Server 2019 1809 | G35: 조기예경보 시스템 | H35: EW | I35: XAMPP 3.2.4 | J35: 2.4.46 | K35: 10.4.14 | L35: 7.4.11 | M35: 1.6.3 | N35: 1.6.3 | O35: 1.6.3 | P35: - | Q35: - | R35: 1.6.3 | S35: 1.6.3 | T35: 완료 | U35: 모니터링S/W
C36: 경기_안성_둔치 | D36: 27.101.130.122 | E36: 20.200.0.100 | F36: Server 2019 1809 | G36: 지능형 통합관제시스템 | H36: EW | I36: XAMPP 3.3.0 | J36: 2.4.54 | K36: 10.4.27 | L36: 7.4.33 | M36: - | N36: 1.6.1 | O36: 1.6.1 | P36: 1.6.1 | Q36: -
C37: 경기_이천_침수차단_관측서버 | D37: 27.101.121.83 | E37: 27.101.121.83 | F37: Server 2022 21H2 | G37: 지능형 통합관제시스템 | H37: EW | I37: XAMPP 3.3.0 | J37: 2.4.54 | K37: 10.4.27 | L37: 7.4.33 | M37: 1.6.3 | N37: 1.6.3 | O37: 1.6.3 | P37: 1.7.0 | Q37: 1.7.0 | R37: 1.6.3 | S37: 1.6.3 | T37: 완료 | V37: 1.9.0 final
C38: 충남_부여_둔치주차_관측서버 | D38: 121.153.186.146 | E38: 50.1.1.120 | F38: Server 2019 1809 | G38: 지능형 통합관제시스템 | H38: EW | I38: XAMPP 3.3.0 | J38: 2.4.53 | K38: 10.4.24 | L38: 7.4.29 | M38: 완료 | N38: 완료 | O38: 완료 | P38: 완료 | Q38: 완료 | T38: 방화벽막힘 | V38: 2.0.0 WPF | W38: 소하천ST
C39: 충북_증평_둔치주차_관측서버 | D39: 221.160.55.184 | E39: 20.200.0.100 | F39: Server 2019 1809 | G39: 둔치주차장 침수차단시스템 | H39: EW | I39: XAMPP 3.3.0 | J39: 2.4.53 | K39: 10.4.24 | L39: 7.4.33 | M39: 1.6.1 | N39: 1.6.1 | O39: 1.6.1 | P39: 1.6.1 | Q39: 1.6.1 | T39: 방화벽막힘 | V39: 2.0.0 Nest.JS
C40: 제주_도청_기상관측_관측서버 | D40: 59.8.86.74 | E40: 59.8.86.74 | F40: Server 2022 21H2 | G40: 지능형 통합관제시스템 | H40: EW | I40: XAMPP 3.3.0 | J40: 2.4.58 | K40: 10.4.32 | L40: 8.2.12 | M40: 1.6.3 | N40: - | O40: - | P40: - | Q40: - | R40: 1.6.3 | S40: 1.6.3 | T40: 방화벽막힘
M41: 완료 | N41: 완료 | O41: 완료 | P41: 완료 | Q41: 완료
C44: 경남_양산_침수차단_관측서버 | D44: 27.101.80.177 | E44: 27.101.80.177 | F44: Server 2022 Std | G44: 지능형 통합관제시스템 | H44: EW | I44: XAMPP 3.3.0 | M44: 1.6.3 | N44: 1.6.3 | O44: 1.6.3 | P44: 1.6.3 | Q44: 1.6.3 | R44: 1.6.3 | S44: 1.6.3 | T44: 완료
B47: 구분 | C47: 시스템 명칭 | D47: 공인 IP | E47: 로컬 IP | F47: OS | G47: 웹페이지 | H47: DB구조 | I47: 서비스 | J47: Apache | K47: MySQL | L47: PHP | M47: 수집 | N47: 방송 | O47: 문자 | P47: 전광판 | Q47: 차단기 | R47: 기상 | S47: 자동실행 | T47: NMS
C48: 강원_강릉_침수차단_관측서버 | D48: 152.99.143.151 | E48: 20.150.0.100 | F48: Server 2019 1809 | G48: 침수차단 | H48: JH | I48: APM | J48: 2.2.14 | K48: 5.1.41 | L48: 5.2.12 | M48: 필요 | N48: - | O48: - | P48: 필요 | Q48: 필요
C49: 강원_고성_침수차단_웹서버 | D49: 152.99.176.92 | E49: 152.99.176.92 | F49: Server 2022 Std 21H2 | G49: 침수차단 | H49: EW | I49: XAMPP 3.3.0 | J49: 2.4.58 | K49: 10.4.32 | L49: 8.2.12 | M49: - | N49: 1.6.3 | O49: 1.6.3 | P49: 1.6.3 | Q49: 1.6.3 | R49: 1.6.3 | S49: 1.6.3 | T49: 완료
C50: 강원_도청_침수중계 | D50: 1.215.113.218 | E50: 1.215.113.218 | H50: JH | I50: - | J50: - | K50: - | L50: - | M50: - | N50: - | O50: - | P50: - | Q50: -
C51: 강원_동해_둔치주차_DB서버 | D51: 211.253.82.243 | E51: 106.4.35.139 | F51: Server 2019 1809 | G51: 보험개발원 | H51: - | I51: - | J51: - | K51: - | L51: - | M51: - | N51: - | O51: - | P51: - | Q51: - | R51: - | S51: - | T51: -
C52: 강원_삼척_침수 | D52: 152.99.147.59 | E52: 152.99.147.59 | F52: Server 2019 1809 | G52: 침수차단 | H52: JH | I52: APM | J52: 2.2.14 | K52: 5.1.41 | L52: 5.2.12 | M52: 필요 | N52: - | O52: - | P52: 필요 | Q52: 완료
C53: 강원_속초_침수 | D53: 152.99.146.64 | E53: 152.99.146.64 | F53: 11 Pro 23H2 | G53: 침수차단 | H53: JH | I53: APM | J53: 2.2.14 | K53: 5.1.41 | L53: 5.2.12 | M53: 필요 | N53: - | O53: - | P53: - | Q53: 필요
C54: 강원_영월_급경사지_관측서버 | D54: 152.99.160.122 | E54: 20.200.0.100 | F54: Server 2019 1809 | G54: 조기예경보 시스템 | H54: EW | I54: XAMPP 3.3.0 | J54: 2.4.53 | K54: 10.4.24 | L54: 7.4.29 | M54: 1.6.3 | N54: 1.6.3 | O54: 1.6.3 | P54: 1.6.3 | Q54: 1.6.3 | R54: 1.6.3 | S54: 1.6.3 | T54: 완료 | U54: NDMS
...
